 * Serving Flask app 'app' (lazy loading)
 * Environment: production
   WARNING: This is a development server. Do not use it in a production deployment.
   Use a production WSGI server instead.
 * Debug mode: on
 * Running on all addresses.
   WARNING: This is a development server. Do not use it in a production deployment.
 * Running on http://172.31.93.205:5003/ (Press CTRL+C to quit)
 * Restarting with stat
 * Debugger is active!
 * Debugger PIN: 120-322-082
210.205.134.193 - - [12/Jan/2022 11:35:34] "GET / HTTP/1.1" 302 -
210.205.134.193 - - [12/Jan/2022 11:35:35] "GET /relogin HTTP/1.1" 200 -
210.205.134.193 - - [12/Jan/2022 11:35:36] "GET /static/css/default.css HTTP/1.1" 200 -
210.205.134.193 - - [12/Jan/2022 11:35:37] "GET /static/css/reset.css HTTP/1.1" 200 -
210.205.134.193 - - [12/Jan/2022 11:35:37] "GET /static/css/main.css HTTP/1.1" 200 -
210.205.134.193 - - [12/Jan/2022 11:35:37] "GET /static/css/common.css HTTP/1.1" 200 -
210.205.134.193 - - [12/Jan/2022 11:35:37] "GET /static/img/test.gif HTTP/1.1" 200 -
210.205.134.193 - - [12/Jan/2022 11:35:40] "GET /favicon.ico HTTP/1.1" 404 -
210.205.134.193 - - [12/Jan/2022 11:35:47] "GET /joinGet HTTP/1.1" 200 -
210.205.134.193 - - [12/Jan/2022 11:35:48] "GET /static/css/default.css HTTP/1.1" 304 -
210.205.134.193 - - [12/Jan/2022 11:35:48] "GET /static/css/common.css HTTP/1.1" 304 -
210.205.134.193 - - [12/Jan/2022 11:35:48] "GET /static/css/main.css HTTP/1.1" 304 -
210.205.134.193 - - [12/Jan/2022 11:35:48] "GET /static/css/reset.css HTTP/1.1" 304 -
210.205.134.193 - - [12/Jan/2022 11:35:49] "GET /static/img/test.gif HTTP/1.1" 304 -
210.205.134.193 - - [12/Jan/2022 11:36:09] "POST /api/membership HTTP/1.1" 500 -
Traceback (most recent call last):
  File "/home/ubuntu/.local/lib/python3.6/site-packages/flask/app.py", line 2091, in __call__
    return self.wsgi_app(environ, start_response)
  File "/home/ubuntu/.local/lib/python3.6/site-packages/flask/app.py", line 2076, in wsgi_app
    response = self.handle_exception(e)
  File "/home/ubuntu/.local/lib/python3.6/site-packages/flask/app.py", line 2073, in wsgi_app
    response = self.full_dispatch_request()
  File "/home/ubuntu/.local/lib/python3.6/site-packages/flask/app.py", line 1518, in full_dispatch_request
    rv = self.handle_user_exception(e)
  File "/home/ubuntu/.local/lib/python3.6/site-packages/flask/app.py", line 1516, in full_dispatch_request
    rv = self.dispatch_request()
  File "/home/ubuntu/.local/lib/python3.6/site-packages/flask/app.py", line 1502, in dispatch_request
    return self.ensure_sync(self.view_functions[rule.endpoint])(**req.view_args)
  File "/home/ubuntu/lsm/hanghae99-cowork01/app.py", line 136, in membership
    find_id = db.user_info.find_one({'ID': id_receive})
  File "/home/ubuntu/.local/lib/python3.6/site-packages/pymongo/collection.py", line 1114, in find_one
    for result in cursor.limit(-1):
  File "/home/ubuntu/.local/lib/python3.6/site-packages/pymongo/cursor.py", line 1159, in next
    if len(self.__data) or self._refresh():
  File "/home/ubuntu/.local/lib/python3.6/site-packages/pymongo/cursor.py", line 1080, in _refresh
    self.__send_message(q)
  File "/home/ubuntu/.local/lib/python3.6/site-packages/pymongo/cursor.py", line 972, in __send_message
    operation, self._unpack_response, address=self.__address)
  File "/home/ubuntu/.local/lib/python3.6/site-packages/pymongo/mongo_client.py", line 1217, in _run_operation
    address=address, retryable=isinstance(operation, message._Query))
  File "/home/ubuntu/.local/lib/python3.6/site-packages/pymongo/mongo_client.py", line 1313, in _retryable_read
    return func(session, server, sock_info, secondary_ok)
  File "/home/ubuntu/.local/lib/python3.6/site-packages/pymongo/mongo_client.py", line 1213, in _cmd
    unpack_res)
  File "/home/ubuntu/.local/lib/python3.6/site-packages/pymongo/server.py", line 129, in run_operation
    _check_command_response(first, sock_info.max_wire_version)
  File "/home/ubuntu/.local/lib/python3.6/site-packages/pymongo/helpers.py", line 170, in _check_command_response
    raise OperationFailure(errmsg, code, response, max_wire_version)
pymongo.errors.OperationFailure: command find requires authentication, full error: {'ok': 0.0, 'errmsg': 'command find requires authentication', 'code': 13, 'codeName': 'Unauthorized'}
210.205.134.193 - - [12/Jan/2022 11:36:16] "POST /api/membership HTTP/1.1" 500 -
Traceback (most recent call last):
  File "/home/ubuntu/.local/lib/python3.6/site-packages/flask/app.py", line 2091, in __call__
    return self.wsgi_app(environ, start_response)
  File "/home/ubuntu/.local/lib/python3.6/site-packages/flask/app.py", line 2076, in wsgi_app
    response = self.handle_exception(e)
  File "/home/ubuntu/.local/lib/python3.6/site-packages/flask/app.py", line 2073, in wsgi_app
    response = self.full_dispatch_request()
  File "/home/ubuntu/.local/lib/python3.6/site-packages/flask/app.py", line 1518, in full_dispatch_request
    rv = self.handle_user_exception(e)
  File "/home/ubuntu/.local/lib/python3.6/site-packages/flask/app.py", line 1516, in full_dispatch_request
    rv = self.dispatch_request()
  File "/home/ubuntu/.local/lib/python3.6/site-packages/flask/app.py", line 1502, in dispatch_request
    return self.ensure_sync(self.view_functions[rule.endpoint])(**req.view_args)
  File "/home/ubuntu/lsm/hanghae99-cowork01/app.py", line 136, in membership
    find_id = db.user_info.find_one({'ID': id_receive})
  File "/home/ubuntu/.local/lib/python3.6/site-packages/pymongo/collection.py", line 1114, in find_one
    for result in cursor.limit(-1):
  File "/home/ubuntu/.local/lib/python3.6/site-packages/pymongo/cursor.py", line 1159, in next
    if len(self.__data) or self._refresh():
  File "/home/ubuntu/.local/lib/python3.6/site-packages/pymongo/cursor.py", line 1080, in _refresh
    self.__send_message(q)
  File "/home/ubuntu/.local/lib/python3.6/site-packages/pymongo/cursor.py", line 972, in __send_message
    operation, self._unpack_response, address=self.__address)
  File "/home/ubuntu/.local/lib/python3.6/site-packages/pymongo/mongo_client.py", line 1217, in _run_operation
    address=address, retryable=isinstance(operation, message._Query))
  File "/home/ubuntu/.local/lib/python3.6/site-packages/pymongo/mongo_client.py", line 1313, in _retryable_read
    return func(session, server, sock_info, secondary_ok)
  File "/home/ubuntu/.local/lib/python3.6/site-packages/pymongo/mongo_client.py", line 1213, in _cmd
    unpack_res)
  File "/home/ubuntu/.local/lib/python3.6/site-packages/pymongo/server.py", line 129, in run_operation
    _check_command_response(first, sock_info.max_wire_version)
  File "/home/ubuntu/.local/lib/python3.6/site-packages/pymongo/helpers.py", line 170, in _check_command_response
    raise OperationFailure(errmsg, code, response, max_wire_version)
pymongo.errors.OperationFailure: command find requires authentication, full error: {'ok': 0.0, 'errmsg': 'command find requires authentication', 'code': 13, 'codeName': 'Unauthorized'}
210.205.134.193 - - [12/Jan/2022 11:36:28] "POST /api/membership HTTP/1.1" 500 -
Traceback (most recent call last):
  File "/home/ubuntu/.local/lib/python3.6/site-packages/flask/app.py", line 2091, in __call__
    return self.wsgi_app(environ, start_response)
  File "/home/ubuntu/.local/lib/python3.6/site-packages/flask/app.py", line 2076, in wsgi_app
    response = self.handle_exception(e)
  File "/home/ubuntu/.local/lib/python3.6/site-packages/flask/app.py", line 2073, in wsgi_app
    response = self.full_dispatch_request()
  File "/home/ubuntu/.local/lib/python3.6/site-packages/flask/app.py", line 1518, in full_dispatch_request
    rv = self.handle_user_exception(e)
  File "/home/ubuntu/.local/lib/python3.6/site-packages/flask/app.py", line 1516, in full_dispatch_request
    rv = self.dispatch_request()
  File "/home/ubuntu/.local/lib/python3.6/site-packages/flask/app.py", line 1502, in dispatch_request
    return self.ensure_sync(self.view_functions[rule.endpoint])(**req.view_args)
  File "/home/ubuntu/lsm/hanghae99-cowork01/app.py", line 136, in membership
    find_id = db.user_info.find_one({'ID': id_receive})
  File "/home/ubuntu/.local/lib/python3.6/site-packages/pymongo/collection.py", line 1114, in find_one
    for result in cursor.limit(-1):
  File "/home/ubuntu/.local/lib/python3.6/site-packages/pymongo/cursor.py", line 1159, in next
    if len(self.__data) or self._refresh():
  File "/home/ubuntu/.local/lib/python3.6/site-packages/pymongo/cursor.py", line 1080, in _refresh
    self.__send_message(q)
  File "/home/ubuntu/.local/lib/python3.6/site-packages/pymongo/cursor.py", line 972, in __send_message
    operation, self._unpack_response, address=self.__address)
  File "/home/ubuntu/.local/lib/python3.6/site-packages/pymongo/mongo_client.py", line 1217, in _run_operation
    address=address, retryable=isinstance(operation, message._Query))
  File "/home/ubuntu/.local/lib/python3.6/site-packages/pymongo/mongo_client.py", line 1313, in _retryable_read
    return func(session, server, sock_info, secondary_ok)
  File "/home/ubuntu/.local/lib/python3.6/site-packages/pymongo/mongo_client.py", line 1213, in _cmd
    unpack_res)
  File "/home/ubuntu/.local/lib/python3.6/site-packages/pymongo/server.py", line 129, in run_operation
    _check_command_response(first, sock_info.max_wire_version)
  File "/home/ubuntu/.local/lib/python3.6/site-packages/pymongo/helpers.py", line 170, in _check_command_response
    raise OperationFailure(errmsg, code, response, max_wire_version)
pymongo.errors.OperationFailure: command find requires authentication, full error: {'ok': 0.0, 'errmsg': 'command find requires authentication', 'code': 13, 'codeName': 'Unauthorized'}
210.205.134.193 - - [12/Jan/2022 11:37:23] "POST /api/membership HTTP/1.1" 500 -
Traceback (most recent call last):
  File "/home/ubuntu/.local/lib/python3.6/site-packages/flask/app.py", line 2091, in __call__
    return self.wsgi_app(environ, start_response)
  File "/home/ubuntu/.local/lib/python3.6/site-packages/flask/app.py", line 2076, in wsgi_app
    response = self.handle_exception(e)
  File "/home/ubuntu/.local/lib/python3.6/site-packages/flask/app.py", line 2073, in wsgi_app
    response = self.full_dispatch_request()
  File "/home/ubuntu/.local/lib/python3.6/site-packages/flask/app.py", line 1518, in full_dispatch_request
    rv = self.handle_user_exception(e)
  File "/home/ubuntu/.local/lib/python3.6/site-packages/flask/app.py", line 1516, in full_dispatch_request
    rv = self.dispatch_request()
  File "/home/ubuntu/.local/lib/python3.6/site-packages/flask/app.py", line 1502, in dispatch_request
    return self.ensure_sync(self.view_functions[rule.endpoint])(**req.view_args)
  File "/home/ubuntu/lsm/hanghae99-cowork01/app.py", line 136, in membership
    find_id = db.user_info.find_one({'ID': id_receive})
  File "/home/ubuntu/.local/lib/python3.6/site-packages/pymongo/collection.py", line 1114, in find_one
    for result in cursor.limit(-1):
  File "/home/ubuntu/.local/lib/python3.6/site-packages/pymongo/cursor.py", line 1159, in next
    if len(self.__data) or self._refresh():
  File "/home/ubuntu/.local/lib/python3.6/site-packages/pymongo/cursor.py", line 1080, in _refresh
    self.__send_message(q)
  File "/home/ubuntu/.local/lib/python3.6/site-packages/pymongo/cursor.py", line 972, in __send_message
    operation, self._unpack_response, address=self.__address)
  File "/home/ubuntu/.local/lib/python3.6/site-packages/pymongo/mongo_client.py", line 1217, in _run_operation
    address=address, retryable=isinstance(operation, message._Query))
  File "/home/ubuntu/.local/lib/python3.6/site-packages/pymongo/mongo_client.py", line 1313, in _retryable_read
    return func(session, server, sock_info, secondary_ok)
  File "/home/ubuntu/.local/lib/python3.6/site-packages/pymongo/mongo_client.py", line 1213, in _cmd
    unpack_res)
  File "/home/ubuntu/.local/lib/python3.6/site-packages/pymongo/server.py", line 129, in run_operation
    _check_command_response(first, sock_info.max_wire_version)
  File "/home/ubuntu/.local/lib/python3.6/site-packages/pymongo/helpers.py", line 170, in _check_command_response
    raise OperationFailure(errmsg, code, response, max_wire_version)
pymongo.errors.OperationFailure: command find requires authentication, full error: {'ok': 0.0, 'errmsg': 'command find requires authentication', 'code': 13, 'codeName': 'Unauthorized'}
 * Detected change in '/home/ubuntu/lsm/hanghae99-cowork01/app.py', reloading
 * Restarting with stat
 * Debugger is active!
 * Debugger PIN: 120-322-082
 * Serving Flask app 'app' (lazy loading)
 * Environment: production
   WARNING: This is a development server. Do not use it in a production deployment.
   Use a production WSGI server instead.
 * Debug mode: on
 * Running on all addresses.
   WARNING: This is a development server. Do not use it in a production deployment.
 * Running on http://172.31.93.205:5003/ (Press CTRL+C to quit)
 * Restarting with stat
 * Debugger is active!
 * Debugger PIN: 120-322-082
210.205.134.193 - - [12/Jan/2022 11:41:58] "GET /joinGet HTTP/1.1" 200 -
210.205.134.193 - - [12/Jan/2022 11:41:59] "GET /static/css/default.css HTTP/1.1" 304 -
210.205.134.193 - - [12/Jan/2022 11:42:00] "GET /static/css/common.css HTTP/1.1" 304 -
210.205.134.193 - - [12/Jan/2022 11:42:00] "GET /static/css/main.css HTTP/1.1" 304 -
210.205.134.193 - - [12/Jan/2022 11:42:00] "GET /static/css/reset.css HTTP/1.1" 304 -
210.205.134.193 - - [12/Jan/2022 11:42:00] "GET /static/img/test.gif HTTP/1.1" 304 -
210.205.134.193 - - [12/Jan/2022 11:42:12] "POST /api/membership HTTP/1.1" 200 -
210.205.134.193 - - [12/Jan/2022 11:42:13] "GET / HTTP/1.1" 302 -
210.205.134.193 - - [12/Jan/2022 11:42:13] "GET /relogin HTTP/1.1" 200 -
210.205.134.193 - - [12/Jan/2022 11:42:15] "GET /static/css/default.css HTTP/1.1" 304 -
210.205.134.193 - - [12/Jan/2022 11:42:15] "GET /static/css/main.css HTTP/1.1" 304 -
210.205.134.193 - - [12/Jan/2022 11:42:15] "GET /static/css/common.css HTTP/1.1" 304 -
210.205.134.193 - - [12/Jan/2022 11:42:15] "GET /static/css/reset.css HTTP/1.1" 304 -
210.205.134.193 - - [12/Jan/2022 11:42:16] "GET /static/img/test.gif HTTP/1.1" 304 -
210.205.134.193 - - [12/Jan/2022 11:42:30] "POST /api/login HTTP/1.1" 500 -
Traceback (most recent call last):
  File "/home/ubuntu/.local/lib/python3.6/site-packages/flask/app.py", line 2091, in __call__
    return self.wsgi_app(environ, start_response)
  File "/home/ubuntu/.local/lib/python3.6/site-packages/flask/app.py", line 2076, in wsgi_app
    response = self.handle_exception(e)
  File "/home/ubuntu/.local/lib/python3.6/site-packages/flask/app.py", line 2073, in wsgi_app
    response = self.full_dispatch_request()
  File "/home/ubuntu/.local/lib/python3.6/site-packages/flask/app.py", line 1518, in full_dispatch_request
    rv = self.handle_user_exception(e)
  File "/home/ubuntu/.local/lib/python3.6/site-packages/flask/app.py", line 1516, in full_dispatch_request
    rv = self.dispatch_request()
  File "/home/ubuntu/.local/lib/python3.6/site-packages/flask/app.py", line 1502, in dispatch_request
    return self.ensure_sync(self.view_functions[rule.endpoint])(**req.view_args)
  File "/home/ubuntu/lsm/hanghae99-cowork01/app.py", line 96, in login
    return jsonify({'result': 'success', 'token': token, 's_msg': '아이디/비밀번호가 맞습니다.'})
  File "/home/ubuntu/.local/lib/python3.6/site-packages/flask/json/__init__.py", line 355, in jsonify
    f"{dumps(data, indent=indent, separators=separators)}\n",
  File "/home/ubuntu/.local/lib/python3.6/site-packages/flask/json/__init__.py", line 133, in dumps
    rv = _json.dumps(obj, **kwargs)
  File "/usr/lib/python3.6/json/__init__.py", line 238, in dumps
    **kw).encode(obj)
  File "/usr/lib/python3.6/json/encoder.py", line 201, in encode
    chunks = list(chunks)
  File "/usr/lib/python3.6/json/encoder.py", line 430, in _iterencode
    yield from _iterencode_dict(o, _current_indent_level)
  File "/usr/lib/python3.6/json/encoder.py", line 404, in _iterencode_dict
    yield from chunks
  File "/usr/lib/python3.6/json/encoder.py", line 437, in _iterencode
    o = _default(o)
  File "/home/ubuntu/.local/lib/python3.6/site-packages/flask/json/__init__.py", line 57, in default
    return super().default(o)
  File "/usr/lib/python3.6/json/encoder.py", line 180, in default
    o.__class__.__name__)
TypeError: Object of type 'bytes' is not JSON serializable
210.205.134.193 - - [12/Jan/2022 11:42:38] "POST /api/login HTTP/1.1" 500 -
Traceback (most recent call last):
  File "/home/ubuntu/.local/lib/python3.6/site-packages/flask/app.py", line 2091, in __call__
    return self.wsgi_app(environ, start_response)
  File "/home/ubuntu/.local/lib/python3.6/site-packages/flask/app.py", line 2076, in wsgi_app
    response = self.handle_exception(e)
  File "/home/ubuntu/.local/lib/python3.6/site-packages/flask/app.py", line 2073, in wsgi_app
    response = self.full_dispatch_request()
  File "/home/ubuntu/.local/lib/python3.6/site-packages/flask/app.py", line 1518, in full_dispatch_request
    rv = self.handle_user_exception(e)
  File "/home/ubuntu/.local/lib/python3.6/site-packages/flask/app.py", line 1516, in full_dispatch_request
    rv = self.dispatch_request()
  File "/home/ubuntu/.local/lib/python3.6/site-packages/flask/app.py", line 1502, in dispatch_request
    return self.ensure_sync(self.view_functions[rule.endpoint])(**req.view_args)
  File "/home/ubuntu/lsm/hanghae99-cowork01/app.py", line 96, in login
    return jsonify({'result': 'success', 'token': token, 's_msg': '아이디/비밀번호가 맞습니다.'})
  File "/home/ubuntu/.local/lib/python3.6/site-packages/flask/json/__init__.py", line 355, in jsonify
    f"{dumps(data, indent=indent, separators=separators)}\n",
  File "/home/ubuntu/.local/lib/python3.6/site-packages/flask/json/__init__.py", line 133, in dumps
    rv = _json.dumps(obj, **kwargs)
  File "/usr/lib/python3.6/json/__init__.py", line 238, in dumps
    **kw).encode(obj)
  File "/usr/lib/python3.6/json/encoder.py", line 201, in encode
    chunks = list(chunks)
  File "/usr/lib/python3.6/json/encoder.py", line 430, in _iterencode
    yield from _iterencode_dict(o, _current_indent_level)
  File "/usr/lib/python3.6/json/encoder.py", line 404, in _iterencode_dict
    yield from chunks
  File "/usr/lib/python3.6/json/encoder.py", line 437, in _iterencode
    o = _default(o)
  File "/home/ubuntu/.local/lib/python3.6/site-packages/flask/json/__init__.py", line 57, in default
    return super().default(o)
  File "/usr/lib/python3.6/json/encoder.py", line 180, in default
    o.__class__.__name__)
TypeError: Object of type 'bytes' is not JSON serializable
210.205.134.193 - - [12/Jan/2022 11:42:41] "POST /api/login HTTP/1.1" 500 -
Traceback (most recent call last):
  File "/home/ubuntu/.local/lib/python3.6/site-packages/flask/app.py", line 2091, in __call__
    return self.wsgi_app(environ, start_response)
  File "/home/ubuntu/.local/lib/python3.6/site-packages/flask/app.py", line 2076, in wsgi_app
    response = self.handle_exception(e)
  File "/home/ubuntu/.local/lib/python3.6/site-packages/flask/app.py", line 2073, in wsgi_app
    response = self.full_dispatch_request()
  File "/home/ubuntu/.local/lib/python3.6/site-packages/flask/app.py", line 1518, in full_dispatch_request
    rv = self.handle_user_exception(e)
  File "/home/ubuntu/.local/lib/python3.6/site-packages/flask/app.py", line 1516, in full_dispatch_request
    rv = self.dispatch_request()
  File "/home/ubuntu/.local/lib/python3.6/site-packages/flask/app.py", line 1502, in dispatch_request
    return self.ensure_sync(self.view_functions[rule.endpoint])(**req.view_args)
  File "/home/ubuntu/lsm/hanghae99-cowork01/app.py", line 96, in login
    return jsonify({'result': 'success', 'token': token, 's_msg': '아이디/비밀번호가 맞습니다.'})
  File "/home/ubuntu/.local/lib/python3.6/site-packages/flask/json/__init__.py", line 355, in jsonify
    f"{dumps(data, indent=indent, separators=separators)}\n",
  File "/home/ubuntu/.local/lib/python3.6/site-packages/flask/json/__init__.py", line 133, in dumps
    rv = _json.dumps(obj, **kwargs)
  File "/usr/lib/python3.6/json/__init__.py", line 238, in dumps
    **kw).encode(obj)
  File "/usr/lib/python3.6/json/encoder.py", line 201, in encode
    chunks = list(chunks)
  File "/usr/lib/python3.6/json/encoder.py", line 430, in _iterencode
    yield from _iterencode_dict(o, _current_indent_level)
  File "/usr/lib/python3.6/json/encoder.py", line 404, in _iterencode_dict
    yield from chunks
  File "/usr/lib/python3.6/json/encoder.py", line 437, in _iterencode
    o = _default(o)
  File "/home/ubuntu/.local/lib/python3.6/site-packages/flask/json/__init__.py", line 57, in default
    return super().default(o)
  File "/usr/lib/python3.6/json/encoder.py", line 180, in default
    o.__class__.__name__)
TypeError: Object of type 'bytes' is not JSON serializable
210.205.134.193 - - [12/Jan/2022 11:42:42] "POST /api/login HTTP/1.1" 500 -
Traceback (most recent call last):
  File "/home/ubuntu/.local/lib/python3.6/site-packages/flask/app.py", line 2091, in __call__
    return self.wsgi_app(environ, start_response)
  File "/home/ubuntu/.local/lib/python3.6/site-packages/flask/app.py", line 2076, in wsgi_app
    response = self.handle_exception(e)
  File "/home/ubuntu/.local/lib/python3.6/site-packages/flask/app.py", line 2073, in wsgi_app
    response = self.full_dispatch_request()
  File "/home/ubuntu/.local/lib/python3.6/site-packages/flask/app.py", line 1518, in full_dispatch_request
    rv = self.handle_user_exception(e)
  File "/home/ubuntu/.local/lib/python3.6/site-packages/flask/app.py", line 1516, in full_dispatch_request
    rv = self.dispatch_request()
  File "/home/ubuntu/.local/lib/python3.6/site-packages/flask/app.py", line 1502, in dispatch_request
    return self.ensure_sync(self.view_functions[rule.endpoint])(**req.view_args)
  File "/home/ubuntu/lsm/hanghae99-cowork01/app.py", line 96, in login
    return jsonify({'result': 'success', 'token': token, 's_msg': '아이디/비밀번호가 맞습니다.'})
  File "/home/ubuntu/.local/lib/python3.6/site-packages/flask/json/__init__.py", line 355, in jsonify
    f"{dumps(data, indent=indent, separators=separators)}\n",
  File "/home/ubuntu/.local/lib/python3.6/site-packages/flask/json/__init__.py", line 133, in dumps
    rv = _json.dumps(obj, **kwargs)
  File "/usr/lib/python3.6/json/__init__.py", line 238, in dumps
    **kw).encode(obj)
  File "/usr/lib/python3.6/json/encoder.py", line 201, in encode
    chunks = list(chunks)
  File "/usr/lib/python3.6/json/encoder.py", line 430, in _iterencode
    yield from _iterencode_dict(o, _current_indent_level)
  File "/usr/lib/python3.6/json/encoder.py", line 404, in _iterencode_dict
    yield from chunks
  File "/usr/lib/python3.6/json/encoder.py", line 437, in _iterencode
    o = _default(o)
  File "/home/ubuntu/.local/lib/python3.6/site-packages/flask/json/__init__.py", line 57, in default
    return super().default(o)
  File "/usr/lib/python3.6/json/encoder.py", line 180, in default
    o.__class__.__name__)
TypeError: Object of type 'bytes' is not JSON serializable
210.205.134.193 - - [12/Jan/2022 11:42:42] "POST /api/login HTTP/1.1" 500 -
Traceback (most recent call last):
  File "/home/ubuntu/.local/lib/python3.6/site-packages/flask/app.py", line 2091, in __call__
    return self.wsgi_app(environ, start_response)
  File "/home/ubuntu/.local/lib/python3.6/site-packages/flask/app.py", line 2076, in wsgi_app
    response = self.handle_exception(e)
  File "/home/ubuntu/.local/lib/python3.6/site-packages/flask/app.py", line 2073, in wsgi_app
    response = self.full_dispatch_request()
  File "/home/ubuntu/.local/lib/python3.6/site-packages/flask/app.py", line 1518, in full_dispatch_request
    rv = self.handle_user_exception(e)
  File "/home/ubuntu/.local/lib/python3.6/site-packages/flask/app.py", line 1516, in full_dispatch_request
    rv = self.dispatch_request()
  File "/home/ubuntu/.local/lib/python3.6/site-packages/flask/app.py", line 1502, in dispatch_request
    return self.ensure_sync(self.view_functions[rule.endpoint])(**req.view_args)
  File "/home/ubuntu/lsm/hanghae99-cowork01/app.py", line 96, in login
    return jsonify({'result': 'success', 'token': token, 's_msg': '아이디/비밀번호가 맞습니다.'})
  File "/home/ubuntu/.local/lib/python3.6/site-packages/flask/json/__init__.py", line 355, in jsonify
    f"{dumps(data, indent=indent, separators=separators)}\n",
  File "/home/ubuntu/.local/lib/python3.6/site-packages/flask/json/__init__.py", line 133, in dumps
    rv = _json.dumps(obj, **kwargs)
  File "/usr/lib/python3.6/json/__init__.py", line 238, in dumps
    **kw).encode(obj)
  File "/usr/lib/python3.6/json/encoder.py", line 201, in encode
    chunks = list(chunks)
  File "/usr/lib/python3.6/json/encoder.py", line 430, in _iterencode
    yield from _iterencode_dict(o, _current_indent_level)
  File "/usr/lib/python3.6/json/encoder.py", line 404, in _iterencode_dict
    yield from chunks
  File "/usr/lib/python3.6/json/encoder.py", line 437, in _iterencode
    o = _default(o)
  File "/home/ubuntu/.local/lib/python3.6/site-packages/flask/json/__init__.py", line 57, in default
    return super().default(o)
  File "/usr/lib/python3.6/json/encoder.py", line 180, in default
    o.__class__.__name__)
TypeError: Object of type 'bytes' is not JSON serializable
210.205.134.193 - - [12/Jan/2022 11:42:42] "POST /api/login HTTP/1.1" 500 -
Traceback (most recent call last):
  File "/home/ubuntu/.local/lib/python3.6/site-packages/flask/app.py", line 2091, in __call__
    return self.wsgi_app(environ, start_response)
  File "/home/ubuntu/.local/lib/python3.6/site-packages/flask/app.py", line 2076, in wsgi_app
    response = self.handle_exception(e)
  File "/home/ubuntu/.local/lib/python3.6/site-packages/flask/app.py", line 2073, in wsgi_app
    response = self.full_dispatch_request()
  File "/home/ubuntu/.local/lib/python3.6/site-packages/flask/app.py", line 1518, in full_dispatch_request
    rv = self.handle_user_exception(e)
  File "/home/ubuntu/.local/lib/python3.6/site-packages/flask/app.py", line 1516, in full_dispatch_request
    rv = self.dispatch_request()
  File "/home/ubuntu/.local/lib/python3.6/site-packages/flask/app.py", line 1502, in dispatch_request
    return self.ensure_sync(self.view_functions[rule.endpoint])(**req.view_args)
  File "/home/ubuntu/lsm/hanghae99-cowork01/app.py", line 96, in login
    return jsonify({'result': 'success', 'token': token, 's_msg': '아이디/비밀번호가 맞습니다.'})
  File "/home/ubuntu/.local/lib/python3.6/site-packages/flask/json/__init__.py", line 355, in jsonify
    f"{dumps(data, indent=indent, separators=separators)}\n",
  File "/home/ubuntu/.local/lib/python3.6/site-packages/flask/json/__init__.py", line 133, in dumps
    rv = _json.dumps(obj, **kwargs)
  File "/usr/lib/python3.6/json/__init__.py", line 238, in dumps
    **kw).encode(obj)
  File "/usr/lib/python3.6/json/encoder.py", line 201, in encode
    chunks = list(chunks)
  File "/usr/lib/python3.6/json/encoder.py", line 430, in _iterencode
    yield from _iterencode_dict(o, _current_indent_level)
  File "/usr/lib/python3.6/json/encoder.py", line 404, in _iterencode_dict
    yield from chunks
  File "/usr/lib/python3.6/json/encoder.py", line 437, in _iterencode
    o = _default(o)
  File "/home/ubuntu/.local/lib/python3.6/site-packages/flask/json/__init__.py", line 57, in default
    return super().default(o)
  File "/usr/lib/python3.6/json/encoder.py", line 180, in default
    o.__class__.__name__)
TypeError: Object of type 'bytes' is not JSON serializable
210.205.134.193 - - [12/Jan/2022 11:42:42] "POST /api/login HTTP/1.1" 500 -
Traceback (most recent call last):
  File "/home/ubuntu/.local/lib/python3.6/site-packages/flask/app.py", line 2091, in __call__
    return self.wsgi_app(environ, start_response)
  File "/home/ubuntu/.local/lib/python3.6/site-packages/flask/app.py", line 2076, in wsgi_app
    response = self.handle_exception(e)
  File "/home/ubuntu/.local/lib/python3.6/site-packages/flask/app.py", line 2073, in wsgi_app
    response = self.full_dispatch_request()
  File "/home/ubuntu/.local/lib/python3.6/site-packages/flask/app.py", line 1518, in full_dispatch_request
    rv = self.handle_user_exception(e)
  File "/home/ubuntu/.local/lib/python3.6/site-packages/flask/app.py", line 1516, in full_dispatch_request
    rv = self.dispatch_request()
  File "/home/ubuntu/.local/lib/python3.6/site-packages/flask/app.py", line 1502, in dispatch_request
    return self.ensure_sync(self.view_functions[rule.endpoint])(**req.view_args)
  File "/home/ubuntu/lsm/hanghae99-cowork01/app.py", line 96, in login
    return jsonify({'result': 'success', 'token': token, 's_msg': '아이디/비밀번호가 맞습니다.'})
  File "/home/ubuntu/.local/lib/python3.6/site-packages/flask/json/__init__.py", line 355, in jsonify
    f"{dumps(data, indent=indent, separators=separators)}\n",
  File "/home/ubuntu/.local/lib/python3.6/site-packages/flask/json/__init__.py", line 133, in dumps
    rv = _json.dumps(obj, **kwargs)
  File "/usr/lib/python3.6/json/__init__.py", line 238, in dumps
    **kw).encode(obj)
  File "/usr/lib/python3.6/json/encoder.py", line 201, in encode
    chunks = list(chunks)
  File "/usr/lib/python3.6/json/encoder.py", line 430, in _iterencode
    yield from _iterencode_dict(o, _current_indent_level)
  File "/usr/lib/python3.6/json/encoder.py", line 404, in _iterencode_dict
    yield from chunks
  File "/usr/lib/python3.6/json/encoder.py", line 437, in _iterencode
    o = _default(o)
  File "/home/ubuntu/.local/lib/python3.6/site-packages/flask/json/__init__.py", line 57, in default
    return super().default(o)
  File "/usr/lib/python3.6/json/encoder.py", line 180, in default
    o.__class__.__name__)
TypeError: Object of type 'bytes' is not JSON serializable
210.205.134.193 - - [12/Jan/2022 11:42:43] "POST /api/login HTTP/1.1" 500 -
Traceback (most recent call last):
  File "/home/ubuntu/.local/lib/python3.6/site-packages/flask/app.py", line 2091, in __call__
    return self.wsgi_app(environ, start_response)
  File "/home/ubuntu/.local/lib/python3.6/site-packages/flask/app.py", line 2076, in wsgi_app
    response = self.handle_exception(e)
  File "/home/ubuntu/.local/lib/python3.6/site-packages/flask/app.py", line 2073, in wsgi_app
    response = self.full_dispatch_request()
  File "/home/ubuntu/.local/lib/python3.6/site-packages/flask/app.py", line 1518, in full_dispatch_request
    rv = self.handle_user_exception(e)
  File "/home/ubuntu/.local/lib/python3.6/site-packages/flask/app.py", line 1516, in full_dispatch_request
    rv = self.dispatch_request()
  File "/home/ubuntu/.local/lib/python3.6/site-packages/flask/app.py", line 1502, in dispatch_request
    return self.ensure_sync(self.view_functions[rule.endpoint])(**req.view_args)
  File "/home/ubuntu/lsm/hanghae99-cowork01/app.py", line 96, in login
    return jsonify({'result': 'success', 'token': token, 's_msg': '아이디/비밀번호가 맞습니다.'})
  File "/home/ubuntu/.local/lib/python3.6/site-packages/flask/json/__init__.py", line 355, in jsonify
    f"{dumps(data, indent=indent, separators=separators)}\n",
  File "/home/ubuntu/.local/lib/python3.6/site-packages/flask/json/__init__.py", line 133, in dumps
    rv = _json.dumps(obj, **kwargs)
  File "/usr/lib/python3.6/json/__init__.py", line 238, in dumps
    **kw).encode(obj)
  File "/usr/lib/python3.6/json/encoder.py", line 201, in encode
    chunks = list(chunks)
  File "/usr/lib/python3.6/json/encoder.py", line 430, in _iterencode
    yield from _iterencode_dict(o, _current_indent_level)
  File "/usr/lib/python3.6/json/encoder.py", line 404, in _iterencode_dict
    yield from chunks
  File "/usr/lib/python3.6/json/encoder.py", line 437, in _iterencode
    o = _default(o)
  File "/home/ubuntu/.local/lib/python3.6/site-packages/flask/json/__init__.py", line 57, in default
    return super().default(o)
  File "/usr/lib/python3.6/json/encoder.py", line 180, in default
    o.__class__.__name__)
TypeError: Object of type 'bytes' is not JSON serializable
210.205.134.193 - - [12/Jan/2022 11:42:44] "POST /api/login HTTP/1.1" 500 -
Traceback (most recent call last):
  File "/home/ubuntu/.local/lib/python3.6/site-packages/flask/app.py", line 2091, in __call__
    return self.wsgi_app(environ, start_response)
  File "/home/ubuntu/.local/lib/python3.6/site-packages/flask/app.py", line 2076, in wsgi_app
    response = self.handle_exception(e)
  File "/home/ubuntu/.local/lib/python3.6/site-packages/flask/app.py", line 2073, in wsgi_app
    response = self.full_dispatch_request()
  File "/home/ubuntu/.local/lib/python3.6/site-packages/flask/app.py", line 1518, in full_dispatch_request
    rv = self.handle_user_exception(e)
  File "/home/ubuntu/.local/lib/python3.6/site-packages/flask/app.py", line 1516, in full_dispatch_request
    rv = self.dispatch_request()
  File "/home/ubuntu/.local/lib/python3.6/site-packages/flask/app.py", line 1502, in dispatch_request
    return self.ensure_sync(self.view_functions[rule.endpoint])(**req.view_args)
  File "/home/ubuntu/lsm/hanghae99-cowork01/app.py", line 96, in login
    return jsonify({'result': 'success', 'token': token, 's_msg': '아이디/비밀번호가 맞습니다.'})
  File "/home/ubuntu/.local/lib/python3.6/site-packages/flask/json/__init__.py", line 355, in jsonify
    f"{dumps(data, indent=indent, separators=separators)}\n",
  File "/home/ubuntu/.local/lib/python3.6/site-packages/flask/json/__init__.py", line 133, in dumps
    rv = _json.dumps(obj, **kwargs)
  File "/usr/lib/python3.6/json/__init__.py", line 238, in dumps
    **kw).encode(obj)
  File "/usr/lib/python3.6/json/encoder.py", line 201, in encode
    chunks = list(chunks)
  File "/usr/lib/python3.6/json/encoder.py", line 430, in _iterencode
    yield from _iterencode_dict(o, _current_indent_level)
  File "/usr/lib/python3.6/json/encoder.py", line 404, in _iterencode_dict
    yield from chunks
  File "/usr/lib/python3.6/json/encoder.py", line 437, in _iterencode
    o = _default(o)
  File "/home/ubuntu/.local/lib/python3.6/site-packages/flask/json/__init__.py", line 57, in default
    return super().default(o)
  File "/usr/lib/python3.6/json/encoder.py", line 180, in default
    o.__class__.__name__)
TypeError: Object of type 'bytes' is not JSON serializable
221.149.189.140 - - [12/Jan/2022 13:23:51] "GET / HTTP/1.1" 302 -
221.149.189.140 - - [12/Jan/2022 13:23:51] "GET /relogin HTTP/1.1" 200 -
221.149.189.140 - - [12/Jan/2022 13:23:51] "GET /static/css/default.css HTTP/1.1" 200 -
221.149.189.140 - - [12/Jan/2022 13:23:52] "GET /static/css/common.css HTTP/1.1" 200 -
221.149.189.140 - - [12/Jan/2022 13:23:52] "GET /static/css/main.css HTTP/1.1" 200 -
221.149.189.140 - - [12/Jan/2022 13:23:52] "GET /static/css/reset.css HTTP/1.1" 200 -
221.149.189.140 - - [12/Jan/2022 13:23:52] "GET /static/img/test.gif HTTP/1.1" 200 -
221.149.189.140 - - [12/Jan/2022 13:23:55] "GET /favicon.ico HTTP/1.1" 404 -
221.149.189.140 - - [12/Jan/2022 13:24:03] "GET /joinGet HTTP/1.1" 200 -
221.149.189.140 - - [12/Jan/2022 13:24:03] "GET /static/css/default.css HTTP/1.1" 304 -
221.149.189.140 - - [12/Jan/2022 13:24:03] "GET /static/css/common.css HTTP/1.1" 304 -
221.149.189.140 - - [12/Jan/2022 13:24:03] "GET /static/css/main.css HTTP/1.1" 304 -
221.149.189.140 - - [12/Jan/2022 13:24:03] "GET /static/css/reset.css HTTP/1.1" 304 -
221.149.189.140 - - [12/Jan/2022 13:24:04] "GET /static/img/test.gif HTTP/1.1" 304 -
221.149.189.140 - - [12/Jan/2022 13:24:25] "POST /api/membership HTTP/1.1" 200 -
221.149.189.140 - - [12/Jan/2022 13:24:26] "GET / HTTP/1.1" 302 -
221.149.189.140 - - [12/Jan/2022 13:24:27] "GET /relogin HTTP/1.1" 200 -
221.149.189.140 - - [12/Jan/2022 13:24:27] "GET /static/css/default.css HTTP/1.1" 304 -
221.149.189.140 - - [12/Jan/2022 13:24:28] "GET /static/css/common.css HTTP/1.1" 304 -
221.149.189.140 - - [12/Jan/2022 13:24:28] "GET /static/css/main.css HTTP/1.1" 304 -
221.149.189.140 - - [12/Jan/2022 13:24:28] "GET /static/css/reset.css HTTP/1.1" 304 -
221.149.189.140 - - [12/Jan/2022 13:24:28] "GET /static/img/test.gif HTTP/1.1" 304 -
221.149.189.140 - - [12/Jan/2022 13:24:33] "POST /api/login HTTP/1.1" 500 -
Traceback (most recent call last):
  File "/home/ubuntu/.local/lib/python3.6/site-packages/flask/app.py", line 2091, in __call__
    return self.wsgi_app(environ, start_response)
  File "/home/ubuntu/.local/lib/python3.6/site-packages/flask/app.py", line 2076, in wsgi_app
    response = self.handle_exception(e)
  File "/home/ubuntu/.local/lib/python3.6/site-packages/flask/app.py", line 2073, in wsgi_app
    response = self.full_dispatch_request()
  File "/home/ubuntu/.local/lib/python3.6/site-packages/flask/app.py", line 1518, in full_dispatch_request
    rv = self.handle_user_exception(e)
  File "/home/ubuntu/.local/lib/python3.6/site-packages/flask/app.py", line 1516, in full_dispatch_request
    rv = self.dispatch_request()
  File "/home/ubuntu/.local/lib/python3.6/site-packages/flask/app.py", line 1502, in dispatch_request
    return self.ensure_sync(self.view_functions[rule.endpoint])(**req.view_args)
  File "/home/ubuntu/lsm/hanghae99-cowork01/app.py", line 96, in login
    return jsonify({'result': 'success', 'token': token, 's_msg': '아이디/비밀번호가 맞습니다.'})
  File "/home/ubuntu/.local/lib/python3.6/site-packages/flask/json/__init__.py", line 355, in jsonify
    f"{dumps(data, indent=indent, separators=separators)}\n",
  File "/home/ubuntu/.local/lib/python3.6/site-packages/flask/json/__init__.py", line 133, in dumps
    rv = _json.dumps(obj, **kwargs)
  File "/usr/lib/python3.6/json/__init__.py", line 238, in dumps
    **kw).encode(obj)
  File "/usr/lib/python3.6/json/encoder.py", line 201, in encode
    chunks = list(chunks)
  File "/usr/lib/python3.6/json/encoder.py", line 430, in _iterencode
    yield from _iterencode_dict(o, _current_indent_level)
  File "/usr/lib/python3.6/json/encoder.py", line 404, in _iterencode_dict
    yield from chunks
  File "/usr/lib/python3.6/json/encoder.py", line 437, in _iterencode
    o = _default(o)
  File "/home/ubuntu/.local/lib/python3.6/site-packages/flask/json/__init__.py", line 57, in default
    return super().default(o)
  File "/usr/lib/python3.6/json/encoder.py", line 180, in default
    o.__class__.__name__)
TypeError: Object of type 'bytes' is not JSON serializable
221.149.189.140 - - [12/Jan/2022 13:24:34] "POST /api/login HTTP/1.1" 500 -
Traceback (most recent call last):
  File "/home/ubuntu/.local/lib/python3.6/site-packages/flask/app.py", line 2091, in __call__
    return self.wsgi_app(environ, start_response)
  File "/home/ubuntu/.local/lib/python3.6/site-packages/flask/app.py", line 2076, in wsgi_app
    response = self.handle_exception(e)
  File "/home/ubuntu/.local/lib/python3.6/site-packages/flask/app.py", line 2073, in wsgi_app
    response = self.full_dispatch_request()
  File "/home/ubuntu/.local/lib/python3.6/site-packages/flask/app.py", line 1518, in full_dispatch_request
    rv = self.handle_user_exception(e)
  File "/home/ubuntu/.local/lib/python3.6/site-packages/flask/app.py", line 1516, in full_dispatch_request
    rv = self.dispatch_request()
  File "/home/ubuntu/.local/lib/python3.6/site-packages/flask/app.py", line 1502, in dispatch_request
    return self.ensure_sync(self.view_functions[rule.endpoint])(**req.view_args)
  File "/home/ubuntu/lsm/hanghae99-cowork01/app.py", line 96, in login
    return jsonify({'result': 'success', 'token': token, 's_msg': '아이디/비밀번호가 맞습니다.'})
  File "/home/ubuntu/.local/lib/python3.6/site-packages/flask/json/__init__.py", line 355, in jsonify
    f"{dumps(data, indent=indent, separators=separators)}\n",
  File "/home/ubuntu/.local/lib/python3.6/site-packages/flask/json/__init__.py", line 133, in dumps
    rv = _json.dumps(obj, **kwargs)
  File "/usr/lib/python3.6/json/__init__.py", line 238, in dumps
    **kw).encode(obj)
  File "/usr/lib/python3.6/json/encoder.py", line 201, in encode
    chunks = list(chunks)
  File "/usr/lib/python3.6/json/encoder.py", line 430, in _iterencode
    yield from _iterencode_dict(o, _current_indent_level)
  File "/usr/lib/python3.6/json/encoder.py", line 404, in _iterencode_dict
    yield from chunks
  File "/usr/lib/python3.6/json/encoder.py", line 437, in _iterencode
    o = _default(o)
  File "/home/ubuntu/.local/lib/python3.6/site-packages/flask/json/__init__.py", line 57, in default
    return super().default(o)
  File "/usr/lib/python3.6/json/encoder.py", line 180, in default
    o.__class__.__name__)
TypeError: Object of type 'bytes' is not JSON serializable
221.149.189.140 - - [12/Jan/2022 13:24:35] "POST /api/login HTTP/1.1" 500 -
